<?xml version="1.0"?>
<!-- This URDF was automatically created by SolidWorks to URDF Exporter! Originally created by Stephen Brawner (brawner@gmail.com) 
     Commit Version: 1.6.0-4-g7f85cfe  Build Version: 1.6.7995.38578
     For more information, please see http://wiki.ros.org/sw_urdf_exporter 
     After generation, multiple changes and additions were required as described in the 2R Robot Modeling Technical Report.-->
<robot  name="scara_sw" xmlns:xacro="http://www.ros.org/wiki/xacro" >

    <xacro:arg name="offset" default="1."/>
    <xacro:arg name="mode" default="position"/>

    <xacro:include filename="camera.xacro" />  <!--Include the camera.xacro file -->

    <xacro:property name="mode" value="$(arg mode)"/>

    <!-- 	___________Joints Control in Gazebo___________-->	
   <xacro:macro name="joint_controller" params="joint p i d cmd_max">

    <xacro:if value="${mode == 'position'}">
      <plugin filename="libignition-gazebo-joint-position-controller-system.so" name="ignition::gazebo::systems::JointPositionController">
              <joint_name>${joint}</joint_name>
              <p_gain>${p}</p_gain>
              <i_gain>${i}</i_gain>
              <d_gain>${d}</d_gain>
              <i_max>${cmd_max}</i_max>
              <i_min>${-cmd_max}</i_min>
              <cmd_max>${cmd_max}</cmd_max>
              <cmd_min>${-cmd_max}</cmd_min>
          </plugin>
    </xacro:if>

    <xacro:if value="${mode == 'velocity'}">
            <plugin filename="libignition-gazebo-joint-controller-system.so" name="ignition::gazebo::systems::JointController">
              <joint_name>${joint}</joint_name>
              <topic>${joint}_cmd_vel</topic>
          </plugin>
    </xacro:if>
    <xacro:if value="${mode == 'effort'}">
        <plugin filename="libignition-gazebo-apply-joint-force-system.so" name="ignition::gazebo::systems::ApplyJointForce">
          <joint_name>${joint}</joint_name>
        </plugin>
    </xacro:if>
   </xacro:macro>


   <gazebo>
    <xacro:joint_controller joint="joint_1" cmd_max="30" p="10" i="0" d="0"/> <!-- 700 0.01 10 -->
    <xacro:joint_controller joint="joint_2" cmd_max="30" p="10" i="0" d="0"/> <!-- 700 0.01 10 -->
   </gazebo>



  <!-- Used for fixing robot to Gazebo base_link -->
  <link name="world"/>

  <joint name="world_joint" type="fixed">
	<origin xyz="0. 0 $(arg offset)" rpy="0 0. 0"/>
    <parent link="world"/>
    <child link="scara/base_link"/>
  </joint>



  <link name="scara/base_link">
    <inertial>
       <origin
         xyz="0 0 0"
        rpy="0 0 -1.57079632679" />
      <mass
        value="15.137" />
      <inertia
        ixx="1.1651"
        ixy="0.00079443"
        ixz="-5.3686E-06"
        iyy="1.1282"
        iyz="-0.004763"
        izz="2.2914" />
    </inertial>
    <visual>
      <origin
        xyz="0 0 0"
        rpy="0 0 -1.57079632679" />
      <geometry>
        <mesh
          filename="file://$(find integ_description)/meshes/base_link.STL" />
      </geometry>
      <material
        name="">
        <color
          rgba="0.66667 0.69804 0.76863 1" />
      </material>
    </visual>
    <collision>
      <origin
        xyz="0 0 0"
        rpy="0 0 -1.57079632679" />
      <geometry>
        <mesh
          filename="file://$(find integ_description)/meshes/base_link.STL" />
      </geometry>
    </collision>
  </link>
  <link name="scara/link_1">
    <inertial>
      <origin
        xyz="0.066529 0.00 0.179392"
        rpy="0 0 0" />

       <mass
        value="7.084761" />
      <inertia
        ixx="0.147885"
        ixy="0.0000"
        ixz="-0.033179"
        iyy="0.196455"
        iyz="0.0000"
        izz="0.055095" /> 
 <!--  Mass and inertia 10x
      <mass
        value="70.84761" />
      <inertia
        ixx="1.47885"
        ixy="0.0000"
        ixz="-0.33179"
        iyy="1.96455"
        iyz="0.0000"
        izz="0.55095" /> -->
    </inertial>
    <visual>
      <origin
        xyz="0 0 0"
        rpy="0 0 0" />
      <geometry>
        <mesh
          filename="file://$(find integ_description)/meshes/link_1.STL" />
      </geometry>
      <material
        name="">
        <color
          rgba="0.89804 0.91765 0.92941 1" />
      </material>
    </visual>
    <collision>
      <origin
        xyz="0 0 0"
        rpy="0 0 0" />
      <geometry>
        <mesh
          filename="file://$(find integ_description)/meshes/link_1.STL" />
      </geometry>
    </collision>
  </link>
  <joint
    name="joint_1"
    type="revolute">
    <origin
      xyz="0 0 0.049"
      rpy="0 0 -1.57079632679" />
    <parent link="scara/base_link" />
    <child link="scara/link_1" />
    <axis
      xyz="0 0 1" />
<!-- Velocity limit from motor max 691Rad/s  divided by Nr=15 -->
<!-- Effort limit nominal 2Nm (Abs max=4Nm) from motor spec times Nr=15 
    <limit
      lower="-3.211405854"
      upper="0.0698132"
      effort="30"
      velocity="46.1" /> 
-->
    <limit
      lower="-3.1"
      upper="0"
      effort="30" 
     velocity="100" /> 
 <!--    Very large friction
	<dynamics
      damping="8.0"
      friction="2.5" />
-->
    <dynamics
      damping="0.4"
      friction="0.9" />
  </joint>
   <!-- Required for ROS control -->
   
    <transmission name="joint_1_transmission">
      <type>transmission_interface/SimpleTransmission</type>
      <joint name="joint_1">
        <hardwareInterface>hardware_interface/EffortJointInterface</hardwareInterface>
        <mechanicalReduction>15</mechanicalReduction>
      </joint>
      <actuator name="joint_1_actuator"/>
    </transmission>

  <link name="scara/ee_frame"/>

  <joint name="ee_joint" type="fixed">
  <origin xyz="0.28002 0.0 0.071" />
    <parent link="scara/link_2" />
    <child link="scara/ee_frame" />
  </joint>


  <link name="scara/link_2">
    <inertial>
      <origin
        xyz="0.082451 0.0 0.045927"
        rpy="0 0 0" />
 <!--    Mass and inertia 10x
	<mass
        value="31.81291" /> -->

<!--       <inertia
        ixx="0.13725"
        ixy="0.00"
        ixz="0.06881"
        iyy="0.67471"
        iyz="0.00"
        izz="0.57501" /> -->
  <!--    Mass and inertia original  
     <mass
        value="3.181291" />
     <inertia
        ixx="0.013725"
        ixy="0.00"
        ixz="0.006881"
        iyy="0.067471"
        iyz="0.00"
        izz="0.057501" /> 
    </inertial> -->
  <!--    Mass and inertia friction match   -->
       <mass
        value="7.084761" />
      <inertia
        ixx="0.147885"
        ixy="0.0000"
        ixz="-0.033179"
        iyy="0.196455"
        iyz="0.0000"
        izz="0.055095" />
    </inertial> 
    <visual>
      <origin
        xyz="0 0 0"
        rpy="0 0 0" />
      <geometry>
        <mesh
          filename="file://$(find integ_description)/meshes/link_2.STL" />
      </geometry>
      <material
        name="">
        <color
          rgba="0.89804 0.91765 0.92941 1" />
      </material>
    </visual>
    <collision>
      <origin
        xyz="0 0 0"
        rpy="0 0 0" />
      <geometry>
        <mesh
          filename="file://$(find integ_description)/meshes/link_2.STL" />
      </geometry>
    </collision>
  </link>
  <joint
    name="joint_2"
    type="revolute">
  <!--  l1 longer by 20cm
	 <origin
      xyz="0.48002 0.0 0.071"
      rpy="0 0 0" /> -->
   <origin
      xyz="0.28002 0.0 0.071"
      rpy="0 0 0" /> 
    <parent link="scara/link_1" />
    <child link="scara/link_2" />
    <axis xyz="0 0 1" />
<!-- Velocity limit from motor max 691Rad/s  divided by Nr=15 -->
<!-- Effort limit nominal 2Nm (Abs max=4) from motor spec times Nr=15 
    <limit
      lower="-2.7925"
      upper="2.7925"
      effort="30" 
     velocity="46.1" /> 
-->
    <limit
      lower="-2"
      upper="2"
      effort="30" 
     velocity="100" /> 
    <dynamics
      damping="0.05"
      friction="0.4" />
<!--   Very large friction
    <dynamics
      damping="5.0"
      friction="1.5" />
-->
  </joint>
    <gazebo>
        <plugin filename="libignition-gazebo-joint-state-publisher-system.so" name="ignition::gazebo::systems::JointStatePublisher"/>
</gazebo>



</robot>
